# 第十章 错误和异常

## 什么是异常

### 错误

从软件方面来说，错误分两个类型，语法上的和逻辑上的。语法错误指的是软件的结构上有错误，导致不能被解释器解释或编译器无法编译。这些错误必须在程序执行前纠正。逻辑错误可能是由于不完整或是不合法的输入所致，这些错误通常分别被称为域错误和范围错误。

当python检测到一个错误时，解释器就会指出当前流已经无法继续执行下去。这时候就出现了异常。

### 异常

对异常的最好描述是：它是因为程序出现了错误而在正常控制流以外采取的行为。这个行为又分为两个阶段：首先是引起异常发生的错误，然后是检测(和采取可能的措施)阶段。

## python中的异常

所有python中的错误，无论是语意上的还是逻辑上的，都是由于和python解释器不相容导致的，其后果就是引发异常。

```python
#参见ipynb文件
```

## 检测和处理异常

异常可以通过try语句来检测。任何在try语句块里的代码都会被监测，检查有无异常发生。

try语句有两种主要形式：try-except和try-finally。这两个语句是互斥的，也就是说你只能使用其中的一种。一个try语句可以对应一个或多个except子句，但只能对应一个finally子句，或是一个try-except-finally复合语句。

### try-except语句

try-except语句(以及其更复杂的形式)定义了进行异常监控的一段代码，并且提供了处理异常的机制。

最常见的try-except语句语法如下所示。它由try块和except块(try_suite和except_suite)组成，也可以有一个可选的错误原因。

```python
try:
    try_suite #监控这里的异常
except Exception[,reason]:
    except_suite #异常处理代码
    
#使用IOError例子说明
try:
    f = open('blah','r')
except Exception,e:
    print 'could not open file: ',e
```

我们加入了探测错误的代码。当引发IOError异常时，我们告诉解释器让它打印出一条诊断信息。程序继续执行，而不像以前的例子那样程序停止运行。

在上面的例子中，我们只捕获IOError异常。任何其他异常不会被我们指定的处理器捕获。

### 核心笔记：忽略代码，继续执行，和向上移交

try语句块中异常发生点后的剩余语句永远不会到达。一旦一个异常被引发，就必须决定控制流下一步到达的位置。剩余代码将被忽略，解释器将搜索处理器，一旦找到，就开始执行处理器中的代码。

如果没有找到合适的处理器，那么异常就向上移交给调用者去处理，这意味着堆栈框架立即回到之前的那个。如果在上层调用者也没找到对应处理器，该异常会继续被向上移交，直到找到合适处理器。如果到达最顶层仍然没有找到对应处理器，那么就认为这个异常是未处理的，python解释器会显示出跟踪记录，然后退出。

### 包装内建函数

举例：把一个字符串表示的数值转换为正确的数值表示形式，而且在过程中要检测并处理可能的错误。

float()内建函数的基本作用是把任意一个数值类型转换为一个浮点型。

```python
def safe_float(obj):
    try:
        return float(obj)
    except ValueError: #搜索并忽略ValueError
        pass        #对错误不错任何处理
    
#改进，异常发生时，也应该显示的返回结果
def safe_float(obj):
    try:
        retval = float(obj)
    except ValueError:
        retval = None
    return retval

#改进，希望返回一个字符串说明输入数据有什么问题
def safe_float(obj):
    try:
        retval = float(obj)
    except ValueError:
        retval = 'could not convert non-number to float'
    return retval
```

### 带有多个except的try语句

except基本语法：

```python
except Exception[, reason]:
    suite_for_exception_Exception
```

你可以把多个except语法连接在一起，处理一个try块中可能发生的多种异常：

```python
except Exception1[,reason1]:
    suite_for_exception_Exception1
except Exception2[,reason2]:
    suite_for_exception_Exception2
```

### 处理多个异常的except语句

我们还可以在一个except子句里处理多个异常。except语句在处理多个异常时要求异常被放在一个元组里：

```python
except (Exception1,Exception2)[,reason]:
    suite_for_Exception1_and_Exception2
```

### 捕获所有异常

如果我们想要捕获所有的异常呢？当然可以！因为异常成为类，因此我们现在有一个异常继承结构可以遵循。

如果查询异常继承的树结构，我们会发现Exception是在最顶层的，所以我们的代码可能看起来会是这样：

```python
try:
    :
except Exception,e:
    #error occurred,log 'e', etc.
```

以上的捕获异常的代码框架会使你忽略掉重要的错误，正常情况下这些错误应该让调用者知道并做一定处理。当然，你可以通过sys.exc_info()获得它，但这样你就不得不去导入sys模块，然后执行函数。

我们可以使用下面这种迂回工作法的代码框架来解决上面提到的问题：

```python
try:
    :
except (KeyboardInterupt,SystemExit):
    #user wants to quit
    raise #reraise to caller
except Exception:
    #handle real errors
```

2.5版本之后，异常被迁移到了新式类(new-style class)上，启用了一个新的"所有异常之母"，这个类叫做BaseException，异常的继承结构有了少许调整：

- BaseException
  - KeyboardInterrupt
  - SystemExit
  - Exception
    - all  other current built-in exceptions 所有当前内建异常

这样，当你已经有了一个Exception处理器后，你不必为这两个异常创建额外的处理器。代码将会是这样：

```python
try:
    :
except Exception,e:
    #handle real errors
```

如果你确实需要捕获所有异常，那就得使用新的BaseException：

```python
try:
    :
except BaseException,e:
    #handle all errors
```

### 核心风格：不要处理并忽略所有错误

python提供给程序员的try-except语句是为了更好的跟踪潜在的错误并在代码里准备好处理异常的逻辑。它的目的是减少程序出错的次数并在出错后仍然能保证程序正常执行。

try-except的作用是提供一个可以提示错误或处理错误的机制，而不是一个错误过滤器。

底线：避免把大片的代码装入try-except中然后使用pass忽略掉错误。你可以捕获特定的异常并忽略它们，或是捕获所有异常并采取特定的动作。不要捕获所有异常，然后忽略掉它们。

### 异常参数

异常也可以有参数，异常引发后它会被传递给异常处理器。当异常被引发后参数是作为附加帮助信息传递给异常处理器的。

异常参数可以在处理器里忽略，但python提供了保存这个值的语法。我们已经在上边接触到相关内容：要想访问提供的异常原因，你必须保留一个变量来保存这个参数。except语句的这个语法可以被扩展为：

```python
#single exception
except Exception[, reason]:
    suite_for_Exception_with_Argument
    
#multiple exceptions
except (Exception1,Exception2,...,ExceptionN)[,reason]:
    suite_for_Exception1_to_ExceptionN_with_Argument
```

reason将会是一个包含来自导致异常的代码的诊断信息的类实例。异常参数自身会组成一个元组，并存储为异常类实例的属性。上边的第一种用法中，reason将会是一个Exception类的实例。

对于大多内建异常，也就是从StandardError派生的异常，这个元组只包含一个指示错误原因的字符串。一般来说，异常的名字已经是一个满意的线索了，但这个错误字符串会提供更多的信息。

无论reason只包含一个字符串或是由错误编号和字符串组成的元组，调用str(reason)总会返回一个良好可读的错误原因。不要忘记reason是一个类实例——这样做你其实是调用类的特殊方法\_\_str\_\_()。

唯一的问题就是某些第三方或是其他外部库并不遵循这个标准协议。**我们推荐你在引发自己的异常时遵循这个标准**。

### 核心风格：遵循异常参数规范

简单地说，如果你引发一个ValueError异常，那么最好提供和解释器引发ValueError时一致的参数信息，以此类推。这样可以保证在保证代码一致性，同时也能避免其他应用程序在使用你的模块时发生错误。

改进上面的safe_float函数。因为每一个异常都将生成自己的异常参数，如果我们选择用这个字符串来而不是我们自定义的信息，可以提供一个更好的线索来指出问题。

```python
def safe_float(object):
    try:
        retval = float(object)
    except (ValueError,TypeError),diag:
        retval = str(diag)
    return retval
```

### else子句

try-except语句段，它的功能和你所见过的其他else没有太多的不同：在try范围中没有异常被检测到时，执行else子句。在else范围的代码执行之前，try范围中的所有代码必须完全成功(也就是，没有引发任何异常)。

### finally子句

finally子句是无论异常是否发生，是否捕获都会执行的一段代码。你可以将finally仅仅配合try一起使用，也可以和try-except(else也是可选的)一起使用。

try-except-else-finally语法的示例：

```python
try:
    A
except MyException:
    B
else:
    C
finally:
    D
    
#等价于
try:
    try:
        A
    except MyException:
        B
    else:
        C
finally:
    D
```

### try-finally语句

另外一种使用finally的方式是finally单独和try连用。这个try-finally语句和try-except区别在于它不是用来捕获异常的。作为替代，它常常用来维持一致的行为而无论异常是否发生。无论try中是否有异常触发，finally代码段都会被执行。

```python
try:
    try_suite
finally:
    finally_suite #无论如何都执行
```

当try范围中产生一个异常时，会立即跳转到finally语句段。**当finally中的所有代码都执行完毕后，会继续向上一层引发异常**。

```python
#版本：捕获打开文件异常
try:
    ccfile = open('carddata.txt')
except IOError:
    log.write('no txns this month\n')
    
#版本二：捕获readlines函数调用失败异常
try:
    ccfile = open('carddata.txt','r')
    txns = ccfile.readlines()
    ccfile.close()
except IOError:
    log.write('no txns this month\n')
    
#版本三：打开成功，但是readlines调用失败，版本二中并没有尝试处理完readlines异常后，尝试关闭文件
try:
    try:
        ccfile=open('carddata.txt','r')
        txns = ccfile.readlines()
        ccfile.close()
    except IOError:
        log.write('no txns this month\n')
finally:
    ccfile.close()
```

很多情况下，异常处理器需要做一些扫尾工作，而如果你在异常处理之前，用finally语句块中释放了某些资源，你就不能再去做这项工作了。简单来说，finally语句块并不是如你所想的是最终(final)的了。

**最终的注意点：如果finally中的代码引发了另一个异常或由于return、break、continue语法而终止，原来的异常将丢失而且无法重新引发。**

## 上下文管理

### with语句

try-except和try-finally的一种特定的配合用法是保证共享的资源的唯一分配，并在任务结束的时候释放它。比如文件、线程资源、简单同步、数据库连接，等待。

with语句的目的在于从流程图中把try、except和finally关键字和资源分配释放相关代码统统去掉。with语法的基本用法如下：

```python
with context_expr [as var]:
    with_suite
```

但是你不能对python的任意符号使用with语句。它仅能工作于支持上下文管理协议(context management protocol)的对象。这显然意味着只有内建了"上下文管理"的对象可以和with一起工作。

支持该协议的对象：

- file
- decimal.Context
- thread.LockType
- threading.Lock
- threading.RLock
- threading.Condition
- threading.Semaphore
- threading.BoundedSemaphore

```python
'''试图打开一个文件，如果成功，把文件对象赋值给f，然后使用迭代器遍历文件中的每一行，当完成遍历时，关闭文件。无论在这段代码的开始、中间还是结束时发生异常，会执行清理的代码，此外文件仍会被自动关闭'''
with open('/etc/passwd','r') as f:
    for eachLine in f:
        #...do stuff with eachLine or f...
```

### *上下文管理协议

我们在这里会介绍兼容协议所必须的对象类型与功能，使其能和with一起工作。

**1.上下文表达式(context_expr),上下文管理器**

当with语句执行时，便执行上下文符号(就是with和as间的内容)来**获取一个上下文管理器**。**上下文管理器的职责是提供一个上下文对象**。这是**通过调用\_\_context\_\_()方法来实现**的(该方法返回一个上下文对象，用于在with语句块中处理细节)。**注意：上下文对象本身就可以是上下文管理器**。所以context_expr即可以是一个真正的上下文管理器，也可以是一个自我管理的上下文对象。

**2.上下文对象，with语句块**

一旦获得了上下文对象，就会调用它的\_\_enter()\_\_方法。它将完成with语句块执行前的所有准备工作。

with语句中有一个可选的as声明变量。如果提供了此变量，以\_\_enter()\_\_返回文件对象并赋值给f。

执行了with语句块之后，无论是和谐的还是引发了异常，都会调用上下文对象的\_\_exit()\_\_方法，它有3个参数。**如果with语句正常结束，三个参数都是None，如果发生异常，三个参数值分别等于调用sys.exc_info()函数返回的三个值:类型(异常类)，值(异常实例)和跟踪记录(traceback)，相应的跟踪记录对象**。

因为上下文管理器主要作用于共享资源，\_\_enter()\_\_,\_\_exit()\_\_方法基本是干的需要分配和释放资源的低层次工作。比如：数据库连接、锁分配、信号量加减、状态管理、打开/关闭文件、异常处理等。

使用contextlib模块来帮助编写对象的上下文管理器。

## 触发异常

到目前为止，我们所见到的异常都是由解释器引发的。由于执行期间的错误而引发。python提供了一种机制让程序员明确的触发异常，这就是raise语句。

### raise语句

**1、语法与惯用法**

raise一般的用法是：

```python
raise [SomeException [,args [,traceback]]]
```

第一个参数，SomeException，是触发异常的名字。如果是，它必须是一个字符串，类或实例。如果有其他参数(arg或traceback)，就必须提供SomeException。

第二个参数为可选的args，传给异常实例的参数。它可以是一个单独的对象也可以是一个对象的元组。当异常发生时，异常的参数总是作为一个元组传入。大多数情况下，单一的字符串用来指示错误的原因。如果传的是元组，通常的组成是一个错误字符串、一个错误编号，可能还有一个错误的地址，比如文件，等等。

最后一项参数，traceback，同样是可选的。如果有的话，则是当异常触发时新生成的一个用于异常-正常化的跟踪记录对象。

**2.更多的特殊/少见的惯用法**

raise语句的用法

| raise语句              | 描述                                                         |
| ---------------------- | ------------------------------------------------------------ |
| raise exclass          | 触发一个异常，从exclass生成一个实例(不含任何异常参数)        |
| raise exclass()        | 同上，但现在不是类；通过函数调用操作符作用于类名生成一个新的exclass实例，同样也没有异常参数 |
| raise exclass,args     | 同上，但同时提供异常参数args，可以是一个参数也可以是元组     |
| raise exclass(args)    | 同上                                                         |
| raise exclass,args,tb  | 同上，但提供一个跟踪记录(traceback)对象tb供使用              |
| raise exclass,instance | 通过实例触发异常(通常是exclass的实例)；如果实例是exclass的子类实例，那么这个新异常的类型会是子类的类型(而不是exclass)；如果实例既不是exclass的实例也不是exclass子类的实例，那么会复制比此实例为异常参数去生成一个新的exclass实例 |
| raise instance         | 通过实例触发异常；异常类型是实例的类型；等价于rase instance.\_\_class\_\_,instance (同上) |
| raise string           | (过时的)触发字符串异常                                       |
| raise string, args     | 同上，但触发伴随着args                                       |
| raise string,args,tb   | 同上                                                         |
| raise                  | 重新触发前一个异常，如果之前没有异常，则触发TypeError        |

## 断言

断言是一句必须等价于布尔真的判定；此外，发生异常也意味着表达式为假。python中断言在运行时构建。

断言可以简简单单的想象为raise-if语句(或者raise-if-not语句)。测试一个表达式，如果返回值是假，触发异常。

断言通过assert语句实现。

### 断言语句

如果断言成功，不采取任何措施，失败则会触发AssertionError(断言错误)的异常。assert的语法如下：

```python
assert expression[, arguments]
```

```python
#断言成功
assert 1==1
assert 2+2==2*2
assert len(['my list',12]) <10
assert range(3) == [0,1,2]
#断言失败
assert 1==0
'''
AssertionError                            Traceback (most recent call last)
<ipython-input-2-ab8cbedd7149> in <module>()
----> 1 assert 1==0

AssertionError: 
'''
#断言失败，同时提供异常参数给assert命令
assert 1==0,'one does not equal zero silly!'
'''
---------------------------------------------------------------------------
AssertionError                            Traceback (most recent call last)
<ipython-input-3-46f3f4adbe25> in <module>()
      1 #提供一个参数给assert命令
----> 2 assert 1==0,'one does not equal zero silly!'

AssertionError: one does not equal zero silly!
'''
```

## 标准异常

| 异常名称                  | 描述                                               |
| ------------------------- | -------------------------------------------------- |
| BaseException             | 所有异常的基类                                     |
| SystemExit                | python解释器请求退出                               |
| KeyboardInterrupt         | 用户中断执行(通常是输入^C)                         |
| Exception                 | 常规错误的基类                                     |
| StopIteration             | 迭代器没有更多的值                                 |
| GeneratorExit             | 生成器(generator)发生异常来通知退出                |
| StandardError             | 所有的内建标准异常的基类                           |
| ArithmeticError           | 所有数值计算错误的基类                             |
| FloatingPointError        | 浮点计算错误                                       |
| OverflowError             | 数值运算超出最大限制                               |
| ZeroDivisionError         | 除(或取模)0                                        |
| AssertionError            | 断言语句失败                                       |
| AttributeError            | 对象没有这个属性                                   |
| EOFError                  | 没有内建输入，到达EOF标记                          |
| EnvironmentError          | 操作系统错误的基类                                 |
| IOError                   | 输入/输出操作失败                                  |
| OSError                   | 操作系统错误                                       |
| WindowsError              | Windows系统调用失败                                |
| ImportError               | 导入模块/对象失败                                  |
| LookupError               | 无效数据查询的基类                                 |
| IndexError                | 序列中没有此索引                                   |
| KeyError                  | 映射中没有这个键                                   |
| MemoryError               | 内存溢出错误(对于python解释器来说不是致命的)       |
| NameError                 | 未声明/初始化对象(没有属性)                        |
| UnboundLocalError         | 访问未初始化的本地变量                             |
| ReferenceError            | 弱引用(weak reference)试图访问已经垃圾回收了的对象 |
| RuntimeError              | 一般的运行时错误                                   |
| NotImplementedError       | 尚未实现的方法                                     |
| SyntaxError               | python语法错误                                     |
| IndentationError          | 缩进错误                                           |
| TabError                  | tab和空格混用                                      |
| SystemError               | 一般的解释器系统错误                               |
| TypeError                 | 对类型无效的操作                                   |
| ValueError                | 传入无效的参数                                     |
| UnicodeError              | Unicode相关错误                                    |
| UnicodeDecodeError        | Unicode解码时错误                                  |
| UnicodeEncodeError        | Unicode编码时错误                                  |
| UnicodeTranslateError     | Unicode转换时错误                                  |
| Warning                   | 警告的基类                                         |
| DeprecationWarning        | 关于被弃用的特征的警告                             |
| FutureWarning             | 关于构造将来语义会有改变的警告                     |
| OverflowWarning           | 旧的关于自动提升为长整型的警告                     |
| PendingDeprecationWarning | 关于特性将会被废弃的警告                           |
| RuntimeWarning            | 可疑的运行时行为的警告                             |
| SyntaxWarning             | 可疑的语法警告                                     |
| UserWarning               | 用户代码生成的警告                                 |

所有的标准/内建异常都是从根异常派生的。

## *创建异常

你可以创建自己的异。一种情况是你想在特定的标准异常和模块异常中添加额外的信息。

## 异常和sys模块

另一种获取异常信息的途径是通过sys模块中exc_info()函数。此功能提供了一个3元组的信息。多于我们单纯用异常参数所能获得。

```python
try:
    float('abc123')
except:
    import sys
    exc_tuple = sys.exc_info()
print exc_tuple
for eachItem in exc_tuple:
    print eachItem
    
'''
(<type 'exceptions.ValueError'>, ValueError('could not convert string to float: abc123',), <traceback object at 0x7f539479f7e8>)
<type 'exceptions.ValueError'>
could not convert string to float: abc123
<traceback object at 0x7f539479f7e8>
'''
```

我们从sys.exc_info()中得到的元组是：

exc_type:异常类

exc_value:异常类的实例

exc_traceback:跟踪记录对象

## 相关模块

| 模块       | 描述                           |
| ---------- | ------------------------------ |
| exceptions | 内建异常(永远不用导入这个模块) |
| contextlib | 为使用with语句的上下文对象工具 |
| sys        | 包含各种异常相关的对象和函数   |



